Workbook
Name Slicer_Sales_Person: #N/A

Sheet Data
C1: Excel Data Analysis
C11: Sales Person | D11: Geography | E11: Product | F11: Amount | G11: Units | I11: Questions | X11: Product | Y11: Cost per unit
C12: Ram Mahesh | D12: New Zealand | E12: 70% Dark Bites | F12: 1624 | G12: 114 | I12: 1 | J12: Quick statistics | X12: Milk Bars | Y12: 9.33
C13: Brien Boise | D13: USA | E13: Choco Coated Almonds | F13: 6706 | G13: 459 | I13: 2 | J13: Exploratory Data Analysis (EDA) with CF | X13: 50% Dark Bites | Y13: 11.7
C14: Husein Augar | D14: USA | E14: Almond Choco | F14: 959 | G14: 147 | I14: 3 | J14: Sales by country (with formulas) | X14: Almond Choco | Y14: 11.88
C15: Carla Molina | D15: Canada | E15: Drinking Coco | F15: 9632 | G15: 288 | I15: 4 | J15: Sales by country (with pivots) | X15: Raspberry Choco | Y15: 11.73
C16: Curtice Advani | D16: UK | E16: White Choc | F16: 2100 | G16: 414 | I16: 5 | J16: Top 5 products by $ per unit | X16: Mint Chip Choco | Y16: 8.79
C17: Ram Mahesh | D17: USA | E17: Peanut Butter Cubes | F17: 8869 | G17: 432 | I17: 6 | J17: Are there any anomalies in the data? | X17: Eclairs | Y17: 3.11
C18: Curtice Advani | D18: Australia | E18: Smooth Sliky Salty | F18: 2681 | G18: 54 | I18: 7 | J18: Best Sales person by country | X18: Drinking Coco | Y18: 6.47
C19: Brien Boise | D19: USA | E19: After Nines | F19: 5012 | G19: 210 | I19: 8 | J19: Profits by product (using products table) - See column Y | X19: 99% Dark & Pure | Y19: 7.64
C20: Ches Bonnell | D20: Australia | E20: 50% Dark Bites | F20: 1281 | G20: 75 | I20: 9 | J20: Dynamic country-level Sales Report | X20: Orange Choco | Y20: 10.62
C21: Gigi Bohling | D21: New Zealand | E21: 50% Dark Bites | F21: 4991 | G21: 12 | I21: 10 | J21: Which products to discontinue? | X21: Spicy Special Slims | Y21: 9
C22: Barr Faughny | D22: UK | E22: White Choc | F22: 1785 | G22: 462 | X22: After Nines | Y22: 9.77
C23: Gunar Cockshoot | D23: New Zealand | E23: Eclairs | F23: 3983 | G23: 144 | I23: Product | J23: Cost per unit | X23: Fruit & Nut Bars | Y23: 6.49
C24: Husein Augar | D24: Australia | E24: Mint Chip Choco | F24: 2646 | G24: 120 | I24: Milk Bars | J24: 9.33 | X24: 85% Dark Bars | Y24: 4.97
C25: Barr Faughny | D25: India | E25: Milk Bars | F25: 252 | G25: 54 | I25: 50% Dark Bites | J25: 11.7 | X25: White Choc | Y25: 13.15
C26: Gunar Cockshoot | D26: USA | E26: White Choc | F26: 2464 | G26: 234 | I26: Almond Choco | J26: 11.88 | X26: Baker's Choco Chips | Y26: 5.6
C27: Gunar Cockshoot | D27: USA | E27: Manuka Honey Choco | F27: 2114 | G27: 66 | I27: Raspberry Choco | J27: 11.73 | X27: Organic Choco Syrup | Y27: 16.73
C28: Curtice Advani | D28: New Zealand | E28: Smooth Sliky Salty | F28: 7693 | G28: 87 | I28: Mint Chip Choco | J28: 8.79 | X28: Caramel Stuffed Bars | Y28: 10.38
C29: Gigi Bohling | D29: India | E29: Orange Choco | F29: 15610 | G29: 339 | I29: Eclairs | J29: 3.11 | X29: Manuka Honey Choco | Y29: 7.16
C30: Carla Molina | D30: India | E30: After Nines | F30: 336 | G30: 144 | I30: Drinking Coco | J30: 6.47 | X30: 70% Dark Bites | Y30: 14.49
C31: Barr Faughny | D31: UK | E31: Orange Choco | F31: 9443 | G31: 162 | I31: 99% Dark & Pure | J31: 7.64 | X31: Smooth Sliky Salty | Y31: 5.79
C32: Husein Augar | D32: India | E32: Fruit & Nut Bars | F32: 8155 | G32: 90 | I32: Orange Choco | J32: 10.62 | X32: Choco Coated Almonds | Y32: 8.65
C33: Brien Boise | D33: Australia | E33: Fruit & Nut Bars | F33: 1701 | G33: 234 | I33: Spicy Special Slims | J33: 9 | X33: Peanut Butter Cubes | Y33: 12.37
C34: Oby Sorrel | D34: Australia | E34: After Nines | F34: 2205 | G34: 141 | I34: After Nines | J34: 9.77
C35: Brien Boise | D35: New Zealand | E35: 99% Dark & Pure | F35: 1771 | G35: 204 | I35: Fruit & Nut Bars | J35: 6.49
C36: Carla Molina | D36: USA | E36: Raspberry Choco | F36: 2114 | G36: 186 | I36: 85% Dark Bars | J36: 4.97
C37: Carla Molina | D37: Canada | E37: Milk Bars | F37: 10311 | G37: 231 | I37: White Choc | J37: 13.15
C38: Gunar Cockshoot | D38: UK | E38: Mint Chip Choco | F38: 21 | G38: 168 | I38: Baker's Choco Chips | J38: 5.6
C39: Oby Sorrel | D39: USA | E39: Orange Choco | F39: 1974 | G39: 195 | I39: Organic Choco Syrup | J39: 16.73
C40: Gigi Bohling | D40: Canada | E40: Fruit & Nut Bars | F40: 6314 | G40: 15 | I40: Caramel Stuffed Bars | J40: 10.38
C41: Oby Sorrel | D41: New Zealand | E41: Fruit & Nut Bars | F41: 4683 | G41: 30 | I41: Manuka Honey Choco | J41: 7.16
C42: Carla Molina | D42: New Zealand | E42: 85% Dark Bars | F42: 6398 | G42: 102 | I42: 70% Dark Bites | J42: 14.49
C43: Barr Faughny | D43: USA | E43: 99% Dark & Pure | F43: 553 | G43: 15 | I43: Smooth Sliky Salty | J43: 5.79
C44: Brien Boise | D44: UK | E44: 70% Dark Bites | F44: 7021 | G44: 183 | I44: Choco Coated Almonds | J44: 8.65
C45: Ram Mahesh | D45: UK | E45: After Nines | F45: 5817 | G45: 12 | I45: Peanut Butter Cubes | J45: 12.37
C46: Carla Molina | D46: UK | E46: 50% Dark Bites | F46: 3976 | G46: 72
C47: Curtice Advani | D47: Australia | E47: Organic Choco Syrup | F47: 1134 | G47: 282
C48: Barr Faughny | D48: UK | E48: Caramel Stuffed Bars | F48: 6027 | G48: 144
C49: Curtice Advani | D49: New Zealand | E49: Mint Chip Choco | F49: 1904 | G49: 405
...

Sheet country level report

Sheet 1
A1: 1 | B1: =Data!J12 -> Quick statistics
C3: Amount | D3: Units
B4: Average | C4: =AVERAGE(data[Amount]) -> 4136.23 | D4: =AVERAGE(data[Units]) -> 152.2
B5: Median | C5: =MEDIAN(data[Amount]) -> 3437 | D5: =MEDIAN(data[Units]) -> 124.5
B6: Min | C6: =MIN(data[Amount]) -> 0 | D6: =MIN(data[Units]) -> 0
B7: Max | C7: =MAX(data[Amount]) -> 16184 | D7: =MAX(data[Units]) -> 525
B8: range | C8: =C7-C6 -> 16184 | D8: =D7-D6 -> 525
B10: First Q | C10: =_xlfn.PERCENTILE.EXC(data[Amount],0.25) -> 1652 | D10: =_xlfn.PERCENTILE.EXC(data[Units],0.25) -> 54
B11: Third Q | C11: =_xlfn.PERCENTILE.EXC(data[Amount],0.75) -> 6245.75 | D11: =_xlfn.PERCENTILE.EXC(data[Units],0.75) -> 223.5
B13: Distinct count of products | E13: =COUNTA(UNIQUE(data[Product])) -> 1

Sheet 2
A1: 2 | B1: =Data!J13 -> Exploratory Data Analysis (EDA) with CF
B3: Sales Person | C3: Geography | D3: Product | E3: Amount | F3: Units
B4: Ram Mahesh | C4: New Zealand | D4: 70% Dark Bites | E4: 1624 | F4: 114
B5: Brien Boise | C5: USA | D5: Choco Coated Almonds | E5: 6706 | F5: 459
B6: Husein Augar | C6: USA | D6: Almond Choco | E6: 959 | F6: 147
B7: Carla Molina | C7: Canada | D7: Drinking Coco | E7: 9632 | F7: 288
B8: Curtice Advani | C8: UK | D8: White Choc | E8: 2100 | F8: 414
B9: Ram Mahesh | C9: USA | D9: Peanut Butter Cubes | E9: 8869 | F9: 432
B10: Curtice Advani | C10: Australia | D10: Smooth Sliky Salty | E10: 2681 | F10: 54
B11: Brien Boise | C11: USA | D11: After Nines | E11: 5012 | F11: 210
B12: Ches Bonnell | C12: Australia | D12: 50% Dark Bites | E12: 1281 | F12: 75
B13: Gigi Bohling | C13: New Zealand | D13: 50% Dark Bites | E13: 4991 | F13: 12
B14: Barr Faughny | C14: UK | D14: White Choc | E14: 1785 | F14: 462
B15: Gunar Cockshoot | C15: New Zealand | D15: Eclairs | E15: 3983 | F15: 144
... B303: Husein Augar | C303: Australia | D303: White Choc | E303: 3850 | F303: 102

Sheet 3
A1: 3 | B1: =Data!J14 -> Sales by country (with formulas)
B3: Country | C3: Amount | D3: Units | H3: Country | I3: Amount | K3: Units
B4: New Zealand | C4: =SUMIFS(data[Amount],data[Geography],B4) -> 218813 | D4: =SUMIFS(data[Units],data[Geography],B4) -> 7431 | H4: India | I4: =SUMIFS(data[Amount],data[Geography],H4) -> 252469 | J4: =I4 -> 252469 | K4: =SUMIFS(data[Units],data[Geography],H4) -> 8760
B5: USA | C5: =SUMIFS(data[Amount],data[Geography],B5) -> 189434 | D5: =SUMIFS(data[Units],data[Geography],B5) -> 10158 | H5: Canada | I5: =SUMIFS(data[Amount],data[Geography],H5) -> 237944 | J5: =I5 -> 237944 | K5: =SUMIFS(data[Units],data[Geography],H5) -> 7302
B6: Canada | C6: =SUMIFS(data[Amount],data[Geography],B6) -> 237944 | D6: =SUMIFS(data[Units],data[Geography],B6) -> 7302 | H6: New Zealand | I6: =SUMIFS(data[Amount],data[Geography],H6) -> 218813 | J6: =I6 -> 218813 | K6: =SUMIFS(data[Units],data[Geography],H6) -> 7431
B7: UK | C7: =SUMIFS(data[Amount],data[Geography],B7) -> 173530 | D7: =SUMIFS(data[Units],data[Geography],B7) -> 5745 | H7: USA | I7: =SUMIFS(data[Amount],data[Geography],H7) -> 189434 | J7: =I7 -> 189434 | K7: =SUMIFS(data[Units],data[Geography],H7) -> 10158
B8: Australia | C8: =SUMIFS(data[Amount],data[Geography],B8) -> 168679 | D8: =SUMIFS(data[Units],data[Geography],B8) -> 6264 | H8: UK | I8: =SUMIFS(data[Amount],data[Geography],H8) -> 173530 | J8: =I8 -> 173530 | K8: =SUMIFS(data[Units],data[Geography],H8) -> 5745
B9: India | C9: =SUMIFS(data[Amount],data[Geography],B9) -> 252469 | D9: =SUMIFS(data[Units],data[Geography],B9) -> 8760 | H9: Australia | I9: =SUMIFS(data[Amount],data[Geography],H9) -> 168679 | J9: =I9 -> 168679 | K9: =SUMIFS(data[Units],data[Geography],H9) -> 6264

Sheet 4
A1: 4 | B1: =Data!J15 -> Sales by country (with pivots)
B3: Row Labels | C3: Sum of Amount | E3: Count of Product | F3: Sum of Units
B4: India | C4: 252469 | D4: 252469 | E4: 58 | F4: 8760
B5: Canada | C5: 237944 | D5: 237944 | E5: 50 | F5: 7302
B6: New Zealand | C6: 218813 | D6: 218813 | E6: 53 | F6: 7431
B7: USA | C7: 189434 | D7: 189434 | E7: 53 | F7: 10158
B8: UK | C8: 173530 | D8: 173530 | E8: 40 | F8: 5745
B9: Australia | C9: 168679 | D9: 168679 | E9: 46 | F9: 6264

Sheet 5
A1: 5 | B1: =Data!J16 -> Top 5 products by $ per unit
B4: Row Labels | C4: Sales_per_unit
B5: Raspberry Choco | C5: 44.990868
B6: Peanut Butter Cubes | C6: 37.303128
B7: 85% Dark Bars | C7: 33.886973
B8: Baker's Choco Chips | C8: 32.80719
B9: After Nines | C9: 32.301657
B10: Grand Total | C10: 35.949565

Sheet 6
A1: 6 | B1: =Data!J17 -> Are there any anomalies in the data?
Q9: Geography | R9: Product | S9: Amount | T9: Units
Q10: New Zealand | R10: 70% Dark Bites | S10: 1624 | T10: 114
Q11: USA | R11: Choco Coated Almonds | S11: 6706 | T11: 459
Q12: USA | R12: Almond Choco | S12: 959 | T12: 147
Q13: Canada | R13: Drinking Coco | S13: 9632 | T13: 288
Q14: UK | R14: White Choc | S14: 2100 | T14: 414
Q15: USA | R15: Peanut Butter Cubes | S15: 8869 | T15: 432
Q16: Australia | R16: Smooth Sliky Salty | S16: 2681 | T16: 54
Q17: USA | R17: After Nines | S17: 5012 | T17: 210
Q18: Australia | R18: 50% Dark Bites | S18: 1281 | T18: 75
Q19: New Zealand | R19: 50% Dark Bites | S19: 4991 | T19: 12
Q20: UK | R20: White Choc | S20: 1785 | T20: 462
Q21: New Zealand | R21: Eclairs | S21: 3983 | T21: 144
... Q309: Australia | R309: White Choc | S309: 3850 | T309: 102

Sheet 7
A1: 7 | B1: =Data!J18 -> Best Sales person by country
B3: Row Labels | C3: Sum of Amount
B4: Australia | C4: 25221
B5: Gigi Bohling | C5: 25221 | G5: Row Labels | H5: Sum of Amount
B6: Canada | C6: 39620 | G6: Australia | H6: 25221
B7: Gigi Bohling | C7: 39620 | G7: Gigi Bohling | H7: 25221
B8: India | C8: 41559 | G8: Canada | H8: 39620
B9: Gigi Bohling | C9: 41559 | G9: Gigi Bohling | H9: 39620
B10: New Zealand | C10: 43568 | G10: India | H10: 41559
B11: Ches Bonnell | C11: 43568 | G11: Gigi Bohling | H11: 41559
B12: UK | C12: 45752 | G12: New Zealand | H12: 43568
B13: Barr Faughny | C13: 45752 | G13: Ches Bonnell | H13: 43568
B14: USA | C14: 38325 | G14: UK | H14: 45752
B15: Ram Mahesh | C15: 38325 | G15: Barr Faughny | H15: 45752
B16: Grand Total | C16: 234045 | G16: USA | H16: 38325
G17: Ram Mahesh | H17: 38325
G18: Grand Total | H18: 234045

Sheet 8
